<?xml version="1.0"?>
<robot name="visual">

  <material name="blue">
    <color rgba="0 0 0.8 1"/>
  </material>
  <material name="black">
    <color rgba="0 0 0 1"/>
  </material>
  <material name="white">
    <color rgba="1 1 1 1"/>
  </material>

  <link name="base_link">
    <visual>
      <geometry>
        <mesh filename="/home/patrick/contact/contact-sim/urdf/mesh/joint_0.stl" scale="1 1 1"/>
      </geometry>
      <origin xyz="-0.0956 -0.0064 -0.0062" rpy="0.0000 0.0000 0.0000"/> <!-- inverse global -->
      <material name="blue"/>
    </visual>
    <collision>
      <geometry>
        <mesh filename="/home/patrick/contact/contact-sim/urdf/mesh/joint_0.stl" scale="1 1 1"/>
      </geometry>
      <origin xyz="-0.0956 -0.0064 -0.0062" rpy="0.0000 0.0000 0.0000"/> <!-- inverse global -->
    </collision>
  </link>

  <!-- INDEX FINGER ************************************************************************************** -->

  <joint name="palm_to_index_1" type="revolute">
    <parent link="base_link"/>
    <child link="index_1"/>
    <limit effort="1000.0" lower="-1" upper="1" velocity="0.5"/>
    <origin xyz="-0.0881 -0.0052 0.0207" rpy="0.0998 -0.0645 0.4137"/> <!-- fwd relative-->
    <axis xyz="0 0 1"/>
  </joint>

  <link name="index_1">
    <visual>
      <geometry>
        <mesh filename="/home/patrick/contact/contact-sim/urdf/mesh/joint_1.stl" scale="1 1 1"/>
      </geometry>
      <origin xyz="-0.0091 -0.0007 -0.0264" rpy="-0.1173 0.0187 -0.4180"/> <!-- inverse global -->
    </visual>
    <collision>
      <geometry>
        <mesh filename="/home/patrick/contact/contact-sim/urdf/mesh/joint_1.stl" scale="1 1 1"/>
      </geometry>
      <origin xyz="-0.0091 -0.0007 -0.0264" rpy="-0.1173 0.0187 -0.4180"/> <!-- inverse global -->
    </collision>
  </link>

  <joint name="index_1_to_index_2" type="revolute">
    <parent link="index_1"/>
    <child link="index_2"/>
    <limit effort="1000.0" lower="-1" upper="1" velocity="0.5"/>
    <origin xyz="-0.0327 0.0040 0.0022" rpy="0.1225 0.0205 0.7585"/> <!-- fwd relative-->
    <axis xyz="0 0 1"/>
  </joint>

  <link name="index_2">
    <visual>
      <geometry>
        <mesh filename="/home/patrick/contact/contact-sim/urdf/mesh/joint_2.stl" scale="1 1 1"/>
      </geometry>
      <origin xyz="0.0145 -0.0229 -0.0257" rpy="-0.1456 -0.1023 -1.1741"/> <!-- inverse global -->
    </visual>
    <collision>
      <geometry>
        <mesh filename="/home/patrick/contact/contact-sim/urdf/mesh/joint_2.stl" scale="1 1 1"/>
      </geometry>
      <origin xyz="0.0145 -0.0229 -0.0257" rpy="-0.1456 -0.1023 -1.1741"/> <!-- inverse global -->
    </collision>
  </link>

  <joint name="index_2_to_index_3" type="revolute">
    <parent link="index_2"/>
    <child link="index_3"/>
    <limit effort="1000.0" lower="-1" upper="1" velocity="0.5"/>
    <origin xyz="-0.0221 -0.0013 -0.0001" rpy="-0.0876 0.0993 0.1844"/> <!-- fwd relative-->
    <axis xyz="0 0 1"/>
  </joint>

  <link name="index_3">
    <visual>
      <geometry>
        <mesh filename="/home/patrick/contact/contact-sim/urdf/mesh/joint_3.stl" scale="1 1 1"/>
      </geometry>
      <origin xyz="0.0344 -0.0259 -0.0247" rpy="-0.0303 -0.0369 -1.3708"/> <!-- inverse global -->
    </visual>
    <collision>
      <geometry>
        <mesh filename="/home/patrick/contact/contact-sim/urdf/mesh/joint_3.stl" scale="1 1 1"/>
      </geometry>
      <origin xyz="0.0344 -0.0259 -0.0247" rpy="-0.0303 -0.0369 -1.3708"/> <!-- inverse global -->
    </collision>
  </link>

  <!-- MIDDLE FINGER ************************************************************************************** -->

  <joint name="palm_to_middle_1" type="revolute">
    <parent link="base_link"/>
    <child link="middle_1"/>
    <limit effort="1000.0" lower="-1" upper="1" velocity="0.5"/>
    <origin xyz="-0.0946 -0.0015 -0.0033" rpy="-0.1258 -0.0180 0.5314"/> <!-- fwd relative-->
    <axis xyz="0 0 1"/>
  </joint>

  <link name="middle_1">
    <visual>
      <geometry>
        <mesh filename="/home/patrick/contact/contact-sim/urdf/mesh/joint_4.stl" scale="1 1 1"/>
      </geometry>
      <origin xyz="-0.0034 -0.0033 -0.0032" rpy="0.0997 0.0790 -0.5264"/> <!-- inverse global -->
    </visual>
    <collision>
      <geometry>
        <mesh filename="/home/patrick/contact/contact-sim/urdf/mesh/joint_4.stl" scale="1 1 1"/>
      </geometry>
      <origin xyz="-0.0034 -0.0033 -0.0032" rpy="0.0997 0.0790 -0.5264"/> <!-- inverse global -->
    </collision>
  </link>

  <joint name="middle_1_to_middle_2" type="revolute">
    <parent link="middle_1"/>
    <child link="middle_2"/>
    <limit effort="1000.0" lower="-1" upper="1" velocity="0.5"/>
    <origin xyz="-0.0312 0.0019 -0.0056" rpy="-0.1508 -0.0021 0.7064"/> <!-- fwd relative-->
    <axis xyz="0 0 1"/>
  </joint>

  <link name="middle_2">
    <visual>
      <geometry>
        <mesh filename="/home/patrick/contact/contact-sim/urdf/mesh/joint_5.stl" scale="1 1 1"/>
      </geometry>
      <origin xyz="0.0178 -0.0221 -0.0010" rpy="0.1487 0.2218 -1.2252"/> <!-- inverse global -->
    </visual>
    <collision>
      <geometry>
        <mesh filename="/home/patrick/contact/contact-sim/urdf/mesh/joint_5.stl" scale="1 1 1"/>
      </geometry>
      <origin xyz="0.0178 -0.0221 -0.0010" rpy="0.1487 0.2218 -1.2252"/> <!-- inverse global -->
    </collision>
  </link>

  <joint name="middle_2_to_middle_3" type="revolute">
    <parent link="middle_2"/>
    <child link="middle_3"/>
    <limit effort="1000.0" lower="-1" upper="1" velocity="0.5"/>
    <origin xyz="-0.0229 -0.0012 -0.0039" rpy="-0.0034 0.0938 0.3380"/> <!-- fwd relative-->
    <axis xyz="0 0 1"/>
  </joint>

  <link name="middle_3">
    <visual>
      <geometry>
        <mesh filename="/home/patrick/contact/contact-sim/urdf/mesh/joint_6.stl" scale="1 1 1"/>
      </geometry>
      <origin xyz="0.0310 -0.0332 0.0058" rpy="0.2450 0.2235 -1.5421"/> <!-- inverse global -->
    </visual>
    <collision>
      <geometry>
        <mesh filename="/home/patrick/contact/contact-sim/urdf/mesh/joint_6.stl" scale="1 1 1"/>
      </geometry>
      <origin xyz="0.0310 -0.0332 0.0058" rpy="0.2450 0.2235 -1.5421"/> <!-- inverse global -->
    </collision>
  </link>

  <!-- RING FINGER ************************************************************************************** -->

  <joint name="palm_to_ring_1" type="revolute">
    <parent link="base_link"/>
    <child link="ring_1"/>
    <limit effort="1000.0" lower="-1" upper="1" velocity="0.5"/>
    <origin xyz="-0.0817 -0.0040 -0.0267" rpy="-0.1066 0.1236 0.6304"/> <!-- fwd relative-->
    <axis xyz="0 0 1"/>
  </joint>

  <link name="ring_1">
    <visual>
      <geometry>
        <mesh filename="/home/patrick/contact/contact-sim/urdf/mesh/joint_10.stl" scale="1 1 1"/>
      </geometry>
      <origin xyz="-0.0151 0.0042 0.0193" rpy="0.1590 -0.0363 -0.6399"/> <!-- inverse global -->
    </visual>
    <collision>
      <geometry>
        <mesh filename="/home/patrick/contact/contact-sim/urdf/mesh/joint_10.stl" scale="1 1 1"/>
      </geometry>
      <origin xyz="-0.0151 0.0042 0.0193" rpy="0.1590 -0.0363 -0.6399"/> <!-- inverse global -->
    </collision>
  </link>

  <joint name="ring_1_to_ring_2" type="revolute">
    <parent link="ring_1"/>
    <child link="ring_2"/>
    <limit effort="1000.0" lower="-1" upper="1" velocity="0.5"/>
    <origin xyz="-0.0283 0.0021 -0.0051" rpy="-0.2674 0.1456 0.6167"/> <!-- fwd relative-->
    <axis xyz="0 0 1"/>
  </joint>

  <link name="ring_2">
    <visual>
      <geometry>
        <mesh filename="/home/patrick/contact/contact-sim/urdf/mesh/joint_11.stl" scale="1 1 1"/>
      </geometry>
      <origin xyz="0.0083 -0.0125 0.0234" rpy="0.3788 0.1741 -1.2609"/> <!-- inverse global -->
    </visual>
    <collision>
      <geometry>
        <mesh filename="/home/patrick/contact/contact-sim/urdf/mesh/joint_11.stl" scale="1 1 1"/>
      </geometry>
      <origin xyz="0.0083 -0.0125 0.0234" rpy="0.3788 0.1741 -1.2609"/> <!-- inverse global -->
    </collision>
  </link>

  <joint name="ring_2_to_ring_3" type="revolute">
    <parent link="ring_2"/>
    <child link="ring_3"/>
    <limit effort="1000.0" lower="-1" upper="1" velocity="0.5"/>
    <origin xyz="-0.0235 -0.0017 -0.0076" rpy="-0.1489 0.1611 0.3628"/> <!-- fwd relative-->
    <axis xyz="0 0 1"/>
  </joint>

  <link name="ring_3">
    <visual>
      <geometry>
        <mesh filename="/home/patrick/contact/contact-sim/urdf/mesh/joint_12.stl" scale="1 1 1"/>
      </geometry>
      <origin xyz="0.0206 -0.0263 0.0313" rpy="0.5385 0.3291 -1.5958"/> <!-- inverse global -->
    </visual>
    <collision>
      <geometry>
        <mesh filename="/home/patrick/contact/contact-sim/urdf/mesh/joint_12.stl" scale="1 1 1"/>
      </geometry>
      <origin xyz="0.0206 -0.0263 0.0313" rpy="0.5385 0.3291 -1.5958"/> <!-- inverse global -->
    </collision>
  </link>

  <!-- PINKY FINGER ************************************************************************************** -->

  <joint name="palm_to_pinky_1" type="revolute">
    <parent link="base_link"/>
    <child link="pinky_1"/>
    <limit effort="1000.0" lower="-1" upper="1" velocity="0.5"/>
    <origin xyz="-0.0687 -0.0099 -0.0432" rpy="-0.3792 0.3168 0.5771"/> <!-- fwd relative-->
    <axis xyz="0 0 1"/>
  </joint>

  <link name="pinky_1">
    <visual>
      <geometry>
        <mesh filename="/home/patrick/contact/contact-sim/urdf/mesh/joint_7.stl" scale="1 1 1"/>
      </geometry>
      <origin xyz="-0.0311 0.0058 0.0332" rpy="0.4876 -0.0406 -0.6485"/> <!-- inverse global -->
    </visual>
    <collision>
      <geometry>
        <mesh filename="/home/patrick/contact/contact-sim/urdf/mesh/joint_7.stl" scale="1 1 1"/>
      </geometry>
      <origin xyz="-0.0311 0.0058 0.0332" rpy="0.4876 -0.0406 -0.6485"/> <!-- inverse global -->
    </collision>
  </link>

  <joint name="pinky_1_to_pinky_2" type="revolute">
    <parent link="pinky_1"/>
    <child link="pinky_2"/>
    <limit effort="1000.0" lower="-1" upper="1" velocity="0.5"/>
    <origin xyz="-0.0170 0.0001 -0.0125" rpy="-0.1899 0.1160 0.4980"/> <!-- fwd relative-->
    <axis xyz="0 0 1"/>
  </joint>

  <link name="pinky_2">
    <visual>
      <geometry>
        <mesh filename="/home/patrick/contact/contact-sim/urdf/mesh/joint_8.stl" scale="1 1 1"/>
      </geometry>
      <origin xyz="-0.0149 0.0032 0.0457" rpy="0.6705 0.0857 -1.1534"/> <!-- inverse global -->
    </visual>
    <collision>
      <geometry>
        <mesh filename="/home/patrick/contact/contact-sim/urdf/mesh/joint_8.stl" scale="1 1 1"/>
      </geometry>
      <origin xyz="-0.0149 0.0032 0.0457" rpy="0.6705 0.0857 -1.1534"/> <!-- inverse global -->
    </collision>
  </link>

  <joint name="pinky_2_to_pinky_3" type="revolute">
    <parent link="pinky_2"/>
    <child link="pinky_3"/>
    <limit effort="1000.0" lower="-1" upper="1" velocity="0.5"/>
    <origin xyz="-0.0158 -0.0007 -0.0103" rpy="-0.3676 0.0735 0.0668"/> <!-- fwd relative-->
    <axis xyz="0 0 1"/>
  </joint>

  <link name="pinky_3">
    <visual>
      <geometry>
        <mesh filename="/home/patrick/contact/contact-sim/urdf/mesh/joint_9.stl" scale="1 1 1"/>
      </geometry>
      <origin xyz="-0.0029 -0.0166 0.0536" rpy="0.8761 0.4033 -1.1832"/> <!-- inverse global -->
    </visual>
    <collision>
      <geometry>
        <mesh filename="/home/patrick/contact/contact-sim/urdf/mesh/joint_9.stl" scale="1 1 1"/>
      </geometry>
      <origin xyz="-0.0029 -0.0166 0.0536" rpy="0.8761 0.4033 -1.1832"/> <!-- inverse global -->
    </collision>
  </link>

  <!-- THUMB FINGER ************************************************************************************** -->

  <joint name="palm_to_thumb_1" type="revolute">
    <parent link="base_link"/>
    <child link="thumb_1"/>
    <limit effort="1000.0" lower="-1" upper="1" velocity="0.5"/>
    <origin xyz="-0.0241 -0.0155 0.0258" rpy="0.8613 -0.2811 -0.0316"/> <!-- fwd relative-->
    <axis xyz="0 0 1"/>
  </joint>

  <link name="thumb_1">
    <visual>
      <geometry>
        <mesh filename="/home/patrick/contact/contact-sim/urdf/mesh/joint_13.stl" scale="1 1 1"/>
      </geometry>
      <origin xyz="-0.0778 -0.0037 -0.0122" rpy="-0.8771 0.2061 -0.1951"/> <!-- inverse global -->
    </visual>
    <collision>
      <geometry>
        <mesh filename="/home/patrick/contact/contact-sim/urdf/mesh/joint_13.stl" scale="1 1 1"/>
      </geometry>
      <origin xyz="-0.0778 -0.0037 -0.0122" rpy="-0.8771 0.2061 -0.1951"/> <!-- inverse global -->
    </collision>
  </link>

  <joint name="thumb_1_to_thumb_2" type="revolute">
    <parent link="thumb_1"/>
    <child link="thumb_2"/>
    <limit effort="1000.0" lower="-1" upper="1" velocity="0.5"/>
    <origin xyz="-0.0196 0.0009 0.0237" rpy="-0.4991 -0.0384 -0.0442"/> <!-- fwd relative-->
    <axis xyz="0 0 1"/>
  </joint>

  <link name="thumb_2">
    <visual>
      <geometry>
        <mesh filename="/home/patrick/contact/contact-sim/urdf/mesh/joint_14.stl" scale="1 1 1"/>
      </geometry>
      <origin xyz="-0.0593 0.0098 -0.0330" rpy="-0.3672 0.2865 -0.0141"/> <!-- inverse global -->
    </visual>
    <collision>
      <geometry>
        <mesh filename="/home/patrick/contact/contact-sim/urdf/mesh/joint_14.stl" scale="1 1 1"/>
      </geometry>
      <origin xyz="-0.0593 0.0098 -0.0330" rpy="-0.3672 0.2865 -0.0141"/> <!-- inverse global -->
    </collision>
  </link>

  <joint name="thumb_2_to_thumb_3" type="revolute">
    <parent link="thumb_2"/>
    <child link="thumb_3"/>
    <limit effort="1000.0" lower="-1" upper="1" velocity="0.5"/>
    <origin xyz="-0.0222 -0.0054 0.0145" rpy="0.5243 -0.1155 0.2532"/> <!-- fwd relative-->
    <axis xyz="0 0 1"/>
  </joint>

  <link name="thumb_3">
    <visual>
      <geometry>
        <mesh filename="/home/patrick/contact/contact-sim/urdf/mesh/joint_15.stl" scale="1 1 1"/>
      </geometry>
      <origin xyz="-0.0373 -0.0010 -0.0497" rpy="-0.9148 0.2100 -0.4362"/> <!-- inverse global -->
    </visual>
    <collision>
      <geometry>
        <mesh filename="/home/patrick/contact/contact-sim/urdf/mesh/joint_15.stl" scale="1 1 1"/>
      </geometry>
      <origin xyz="-0.0373 -0.0010 -0.0497" rpy="-0.9148 0.2100 -0.4362"/> <!-- inverse global -->
    </collision>
  </link>
</robot>
