<?xml version="1.0"?>
<robot name="visual">

  <material name="blue">
    <color rgba="0 0 0.8 1"/>
  </material>
  <material name="black">
    <color rgba="0 0 0 1"/>
  </material>
  <material name="white">
    <color rgba="1 1 1 1"/>
  </material>

  <link name="base_link">
    <visual>
      <geometry>
        <mesh filename="file:///home/patrick/contact/contact-sim/mesh/joint_0.stl" scale="1 1 1"/>
      </geometry>
      <origin xyz="-0.0956 0.0064 0.0062" rpy="-3.1416 0.0000 -0.0000"/> <!-- inverse global -->
      <material name="blue"/>
    </visual>
  </link>

  <joint name="palm_to_index_1" type="continuous">
    <parent link="base_link"/>
    <child link="index_1"/>
    <!-- <limit effort="1000.0" lower="-1" upper="1" velocity="0.5"/> -->
    <origin xyz="-0.0881 -0.0052 0.0207" rpy="0.1656 0.0305 0.1494"/> <!-- fwd relative j0-j1-->
  </joint>

  <link name="index_1">
    <visual>
      <geometry>
        <mesh filename="file:///home/patrick/contact/contact-sim/mesh/joint_1.stl" scale="1 1 1"/>
      </geometry>
      <origin xyz="-0.0053 0.0100 -0.0165" rpy="2.9822 -0.0544 -0.1426"/> <!-- inverse global -->
    </visual>
  </link>

  <joint name="index_1_to_index_2" type="continuous">
    <parent link="index_1"/>
    <child link="index_2"/>
    <!-- <limit effort="1000.0" lower="-1" upper="1" velocity="0.5"/> -->
    <origin xyz="-0.0327 0.0040 0.0022" rpy="-0.0144 -0.0299 0.1765"/>
  </joint>

  <link name="index_2">
    <visual>
      <geometry>
        <mesh filename="file:///home/patrick/contact/contact-sim/mesh/joint_2.stl" scale="1 1 1"/>
      </geometry>
      <origin xyz="0.0274 0.0014 -0.0196" rpy="2.9864 -0.0214 -0.3190"/>
    </visual>
  </link>

  <joint name="index_2_to_index_3" type="floating">
    <parent link="index_2"/>
    <child link="index_3"/>
    <!-- <limit effort="1000.0" lower="-1" upper="1" velocity="0.5"/> -->
    <origin xyz="-0.0221 -0.0013 -0.0001" rpy="0.0407 0.0358 0.1450"/>
  </joint>

  <link name="index_3">
    <visual>
      <geometry>
        <mesh filename="file:///home/patrick/contact/contact-sim/mesh/joint_3.stl" scale="1 1 1"/>
      </geometry>
      <origin xyz="0.0501 -0.0053 -0.0175" rpy="2.9659 -0.0716 -0.4623"/>
    </visual>
  </link>
</robot>
