<?xml version="1.0"?>
<robot name="visual">

  <material name="blue">
    <color rgba="0 0 0.8 1"/>
  </material>
  <material name="black">
    <color rgba="0 0 0 1"/>
  </material>
  <material name="white">
    <color rgba="1 1 1 1"/>
  </material>

  <link name="base_link">
    <visual>
      <geometry>
        <mesh filename="file:///home/patrick/contact/contact-sim/urdf/mesh/joint_0.stl" scale="1 1 1"/>
      </geometry>
      <origin xyz="0.0000 0.0000 0.0000" rpy="0.0000 0.0000 0.0000"/> <!-- inverse global -->
      <material name="blue"/>
    </visual>
    <collision>
      <geometry>
        <mesh filename="file:///home/patrick/contact/contact-sim/urdf/mesh/joint_0.stl" scale="1 1 1"/>
      </geometry>
      <origin xyz="0.0000 0.0000 0.0000" rpy="0.0000 0.0000 0.0000"/> <!-- inverse global -->
    </collision>
  </link>

  <!-- INDEX FINGER ************************************************************************************** -->

  <joint name="palm_to_index_1" type="revolute">
    <parent link="base_link"/>
    <child link="index_1"/>
    <limit effort="1000.0" lower="-1" upper="1" velocity="0.5"/>
    <origin xyz="-0.0881 -0.0052 0.0207" rpy="0.0000 0.0000 0.0000"/> <!-- fwd relative-->
    <axis xyz="0.0573 -0.3832 0.9219"/>
  </joint>

  <link name="index_1">
    <visual>
      <geometry>
        <mesh filename="file:///home/patrick/contact/contact-sim/urdf/mesh/joint_1.stl" scale="1 1 1"/>
      </geometry>
      <origin xyz="0.0000 0.0000 0.0000" rpy="0.0000 0.0000 0.0000"/> <!-- inverse global -->
    </visual>
    <collision>
      <geometry>
        <mesh filename="file:///home/patrick/contact/contact-sim/urdf/mesh/joint_1.stl" scale="1 1 1"/>
      </geometry>
      <origin xyz="0.0000 0.0000 0.0000" rpy="0.0000 0.0000 0.0000"/> <!-- inverse global -->
    </collision>
  </link>

  <joint name="index_1_to_index_2" type="revolute">
    <parent link="index_1"/>
    <child link="index_2"/>
    <limit effort="1000.0" lower="-1" upper="1" velocity="0.5"/>
    <origin xyz="-0.0327 0.0040 0.0022" rpy="0.0000 0.0000 0.0000"/> <!-- fwd relative-->
    <axis xyz="0.1380 -0.0369 0.9897"/>
  </joint>

  <link name="index_2">
    <visual>
      <geometry>
        <mesh filename="file:///home/patrick/contact/contact-sim/urdf/mesh/joint_2.stl" scale="1 1 1"/>
      </geometry>
      <origin xyz="0.0000 0.0000 0.0000" rpy="0.0000 0.0000 0.0000"/> <!-- inverse global -->
    </visual>
    <collision>
      <geometry>
        <mesh filename="file:///home/patrick/contact/contact-sim/urdf/mesh/joint_2.stl" scale="1 1 1"/>
      </geometry>
      <origin xyz="0.0000 0.0000 0.0000" rpy="0.0000 0.0000 0.0000"/> <!-- inverse global -->
    </collision>
  </link>

  <joint name="index_2_to_index_3" type="revolute">
    <parent link="index_2"/>
    <child link="index_3"/>
    <limit effort="1000.0" lower="-1" upper="1" velocity="0.5"/>
    <origin xyz="-0.0222 -0.0013 -0.0001" rpy="0.0000 0.0000 0.0000"/> <!-- fwd relative-->
    <axis xyz="-0.1161 0.4997 0.8584"/>
  </joint>

  <link name="index_3">
    <visual>
      <geometry>
        <mesh filename="file:///home/patrick/contact/contact-sim/urdf/mesh/joint_3.stl" scale="1 1 1"/>
      </geometry>
      <origin xyz="0.0000 0.0000 0.0000" rpy="0.0000 0.0000 0.0000"/> <!-- inverse global -->
    </visual>
    <collision>
      <geometry>
        <mesh filename="file:///home/patrick/contact/contact-sim/urdf/mesh/joint_3.stl" scale="1 1 1"/>
      </geometry>
      <origin xyz="0.0000 0.0000 0.0000" rpy="0.0000 0.0000 0.0000"/> <!-- inverse global -->
    </collision>
  </link>

  <!-- MIDDLE FINGER ************************************************************************************** -->

  <joint name="palm_to_middle_1" type="revolute">
    <parent link="base_link"/>
    <child link="middle_1"/>
    <limit effort="1000.0" lower="-1" upper="1" velocity="0.5"/>
    <origin xyz="-0.0947 -0.0015 -0.0034" rpy="0.0000 0.0000 0.0000"/> <!-- fwd relative-->
    <axis xyz="-0.4354 -0.1759 0.8829"/>
  </joint>

  <link name="middle_1">
    <visual>
      <geometry>
        <mesh filename="file:///home/patrick/contact/contact-sim/urdf/mesh/joint_4.stl" scale="1 1 1"/>
      </geometry>
      <origin xyz="0.0000 0.0000 0.0000" rpy="0.0000 0.0000 0.0000"/> <!-- inverse global -->
    </visual>
    <collision>
      <geometry>
        <mesh filename="file:///home/patrick/contact/contact-sim/urdf/mesh/joint_4.stl" scale="1 1 1"/>
      </geometry>
      <origin xyz="0.0000 0.0000 0.0000" rpy="0.0000 0.0000 0.0000"/> <!-- inverse global -->
    </collision>
  </link>

  <joint name="middle_1_to_middle_2" type="revolute">
    <parent link="middle_1"/>
    <child link="middle_2"/>
    <limit effort="1000.0" lower="-1" upper="1" velocity="0.5"/>
    <origin xyz="-0.0312 0.0019 -0.0056" rpy="0.0000 0.0000 0.0000"/> <!-- fwd relative-->
    <axis xyz="0.0530 -0.0978 0.9938"/>
  </joint>

  <link name="middle_2">
    <visual>
      <geometry>
        <mesh filename="file:///home/patrick/contact/contact-sim/urdf/mesh/joint_5.stl" scale="1 1 1"/>
      </geometry>
      <origin xyz="0.0000 0.0000 0.0000" rpy="0.0000 0.0000 0.0000"/> <!-- inverse global -->
    </visual>
    <collision>
      <geometry>
        <mesh filename="file:///home/patrick/contact/contact-sim/urdf/mesh/joint_5.stl" scale="1 1 1"/>
      </geometry>
      <origin xyz="0.0000 0.0000 0.0000" rpy="0.0000 0.0000 0.0000"/> <!-- inverse global -->
    </collision>
  </link>

  <joint name="middle_2_to_middle_3" type="revolute">
    <parent link="middle_2"/>
    <child link="middle_3"/>
    <limit effort="1000.0" lower="-1" upper="1" velocity="0.5"/>
    <origin xyz="-0.0229 -0.0013 -0.0039" rpy="0.0000 0.0000 0.0000"/> <!-- fwd relative-->
    <axis xyz="0.0621 0.1374 0.9886"/>
  </joint>

  <link name="middle_3">
    <visual>
      <geometry>
        <mesh filename="file:///home/patrick/contact/contact-sim/urdf/mesh/joint_6.stl" scale="1 1 1"/>
      </geometry>
      <origin xyz="0.0000 0.0000 0.0000" rpy="0.0000 0.0000 0.0000"/> <!-- inverse global -->
    </visual>
    <collision>
      <geometry>
        <mesh filename="file:///home/patrick/contact/contact-sim/urdf/mesh/joint_6.stl" scale="1 1 1"/>
      </geometry>
      <origin xyz="0.0000 0.0000 0.0000" rpy="0.0000 0.0000 0.0000"/> <!-- inverse global -->
    </collision>
  </link>

  <!-- RING FINGER ************************************************************************************** -->

  <joint name="palm_to_ring_1" type="revolute">
    <parent link="base_link"/>
    <child link="ring_1"/>
    <limit effort="1000.0" lower="-1" upper="1" velocity="0.5"/>
    <origin xyz="-0.0817 -0.0040 -0.0267" rpy="0.0000 0.0000 0.0000"/> <!-- fwd relative-->
    <axis xyz="-0.3497 0.1281 0.9281"/>
  </joint>

  <link name="ring_1">
    <visual>
      <geometry>
        <mesh filename="file:///home/patrick/contact/contact-sim/urdf/mesh/joint_10.stl" scale="1 1 1"/>
      </geometry>
      <origin xyz="0.0000 0.0000 0.0000" rpy="0.0000 0.0000 0.0000"/> <!-- inverse global -->
    </visual>
    <collision>
      <geometry>
        <mesh filename="file:///home/patrick/contact/contact-sim/urdf/mesh/joint_10.stl" scale="1 1 1"/>
      </geometry>
      <origin xyz="0.0000 0.0000 0.0000" rpy="0.0000 0.0000 0.0000"/> <!-- inverse global -->
    </collision>
  </link>

  <joint name="ring_1_to_ring_2" type="revolute">
    <parent link="ring_1"/>
    <child link="ring_2"/>
    <limit effort="1000.0" lower="-1" upper="1" velocity="0.5"/>
    <origin xyz="-0.0283 0.0021 -0.0051" rpy="0.0000 0.0000 0.0000"/> <!-- fwd relative-->
    <axis xyz="-0.4653 0.2350 0.8534"/>
  </joint>

  <link name="ring_2">
    <visual>
      <geometry>
        <mesh filename="file:///home/patrick/contact/contact-sim/urdf/mesh/joint_11.stl" scale="1 1 1"/>
      </geometry>
      <origin xyz="0.0000 0.0000 0.0000" rpy="0.0000 0.0000 0.0000"/> <!-- inverse global -->
    </visual>
    <collision>
      <geometry>
        <mesh filename="file:///home/patrick/contact/contact-sim/urdf/mesh/joint_11.stl" scale="1 1 1"/>
      </geometry>
      <origin xyz="0.0000 0.0000 0.0000" rpy="0.0000 0.0000 0.0000"/> <!-- inverse global -->
    </collision>
  </link>

  <joint name="ring_2_to_ring_3" type="revolute">
    <parent link="ring_2"/>
    <child link="ring_3"/>
    <limit effort="1000.0" lower="-1" upper="1" velocity="0.5"/>
    <origin xyz="-0.0235 -0.0017 -0.0076" rpy="0.0000 0.0000 0.0000"/> <!-- fwd relative-->
    <axis xyz="-0.2219 -0.0481 0.9739"/>
  </joint>

  <link name="ring_3">
    <visual>
      <geometry>
        <mesh filename="file:///home/patrick/contact/contact-sim/urdf/mesh/joint_12.stl" scale="1 1 1"/>
      </geometry>
      <origin xyz="0.0000 0.0000 0.0000" rpy="0.0000 0.0000 0.0000"/> <!-- inverse global -->
    </visual>
    <collision>
      <geometry>
        <mesh filename="file:///home/patrick/contact/contact-sim/urdf/mesh/joint_12.stl" scale="1 1 1"/>
      </geometry>
      <origin xyz="0.0000 0.0000 0.0000" rpy="0.0000 0.0000 0.0000"/> <!-- inverse global -->
    </collision>
  </link>

  <!-- PINKY FINGER ************************************************************************************** -->

  <joint name="palm_to_pinky_1" type="revolute">
    <parent link="base_link"/>
    <child link="pinky_1"/>
    <limit effort="1000.0" lower="-1" upper="1" velocity="0.5"/>
    <origin xyz="-0.0688 -0.0099 -0.0432" rpy="0.0000 0.0000 0.0000"/> <!-- fwd relative-->
    <axis xyz="-0.7138 0.1337 0.6875"/>
  </joint>

  <link name="pinky_1">
    <visual>
      <geometry>
        <mesh filename="file:///home/patrick/contact/contact-sim/urdf/mesh/joint_7.stl" scale="1 1 1"/>
      </geometry>
      <origin xyz="0.0000 0.0000 0.0000" rpy="0.0000 0.0000 0.0000"/> <!-- inverse global -->
    </visual>
    <collision>
      <geometry>
        <mesh filename="file:///home/patrick/contact/contact-sim/urdf/mesh/joint_7.stl" scale="1 1 1"/>
      </geometry>
      <origin xyz="0.0000 0.0000 0.0000" rpy="0.0000 0.0000 0.0000"/> <!-- inverse global -->
    </collision>
  </link>

  <joint name="pinky_1_to_pinky_2" type="revolute">
    <parent link="pinky_1"/>
    <child link="pinky_2"/>
    <limit effort="1000.0" lower="-1" upper="1" velocity="0.5"/>
    <origin xyz="-0.0170 0.0001 -0.0125" rpy="0.0000 0.0000 0.0000"/> <!-- fwd relative-->
    <axis xyz="0.2096 0.2490 0.9455"/>
  </joint>

  <link name="pinky_2">
    <visual>
      <geometry>
        <mesh filename="file:///home/patrick/contact/contact-sim/urdf/mesh/joint_8.stl" scale="1 1 1"/>
      </geometry>
      <origin xyz="0.0000 0.0000 0.0000" rpy="0.0000 0.0000 0.0000"/> <!-- inverse global -->
    </visual>
    <collision>
      <geometry>
        <mesh filename="file:///home/patrick/contact/contact-sim/urdf/mesh/joint_8.stl" scale="1 1 1"/>
      </geometry>
      <origin xyz="0.0000 0.0000 0.0000" rpy="0.0000 0.0000 0.0000"/> <!-- inverse global -->
    </collision>
  </link>

  <joint name="pinky_2_to_pinky_3" type="revolute">
    <parent link="pinky_2"/>
    <child link="pinky_3"/>
    <limit effort="1000.0" lower="-1" upper="1" velocity="0.5"/>
    <origin xyz="-0.0159 -0.0007 -0.0103" rpy="0.0000 0.0000 0.0000"/> <!-- fwd relative-->
    <axis xyz="-0.7858 -0.0810 0.6132"/>
  </joint>

  <link name="pinky_3">
    <visual>
      <geometry>
        <mesh filename="file:///home/patrick/contact/contact-sim/urdf/mesh/joint_9.stl" scale="1 1 1"/>
      </geometry>
      <origin xyz="0.0000 0.0000 0.0000" rpy="0.0000 0.0000 0.0000"/> <!-- inverse global -->
    </visual>
    <collision>
      <geometry>
        <mesh filename="file:///home/patrick/contact/contact-sim/urdf/mesh/joint_9.stl" scale="1 1 1"/>
      </geometry>
      <origin xyz="0.0000 0.0000 0.0000" rpy="0.0000 0.0000 0.0000"/> <!-- inverse global -->
    </collision>
  </link>

  <!-- THUMB FINGER ************************************************************************************** -->

  <joint name="palm_to_thumb_1" type="revolute">
    <parent link="base_link"/>
    <child link="thumb_1"/>
    <limit effort="1000.0" lower="-1" upper="1" velocity="0.5"/>
    <origin xyz="-0.0241 -0.0155 0.0258" rpy="0.0000 0.0000 0.0000"/> <!-- fwd relative-->
    <axis xyz="0.7916 -0.5713 -0.2166"/>
  </joint>

  <link name="thumb_1">
    <visual>
      <geometry>
        <mesh filename="file:///home/patrick/contact/contact-sim/urdf/mesh/joint_13.stl" scale="1 1 1"/>
      </geometry>
      <origin xyz="0.0000 0.0000 0.0000" rpy="0.0000 0.0000 0.0000"/> <!-- inverse global -->
    </visual>
    <collision>
      <geometry>
        <mesh filename="file:///home/patrick/contact/contact-sim/urdf/mesh/joint_13.stl" scale="1 1 1"/>
      </geometry>
      <origin xyz="0.0000 0.0000 0.0000" rpy="0.0000 0.0000 0.0000"/> <!-- inverse global -->
    </collision>
  </link>

  <joint name="thumb_1_to_thumb_2" type="revolute">
    <parent link="thumb_1"/>
    <child link="thumb_2"/>
    <limit effort="1000.0" lower="-1" upper="1" velocity="0.5"/>
    <origin xyz="-0.0196 0.0009 0.0237" rpy="0.0000 0.0000 0.0000"/> <!-- fwd relative-->
    <axis xyz="0.7080 -0.7041 -0.0543"/>
  </joint>

  <link name="thumb_2">
    <visual>
      <geometry>
        <mesh filename="file:///home/patrick/contact/contact-sim/urdf/mesh/joint_14.stl" scale="1 1 1"/>
      </geometry>
      <origin xyz="0.0000 0.0000 0.0000" rpy="0.0000 0.0000 0.0000"/> <!-- inverse global -->
    </visual>
    <collision>
      <geometry>
        <mesh filename="file:///home/patrick/contact/contact-sim/urdf/mesh/joint_14.stl" scale="1 1 1"/>
      </geometry>
      <origin xyz="0.0000 0.0000 0.0000" rpy="0.0000 0.0000 0.0000"/> <!-- inverse global -->
    </collision>
  </link>

  <joint name="thumb_2_to_thumb_3" type="revolute">
    <parent link="thumb_2"/>
    <child link="thumb_3"/>
    <limit effort="1000.0" lower="-1" upper="1" velocity="0.5"/>
    <origin xyz="-0.0222 -0.0054 0.0145" rpy="0.0000 0.0000 0.0000"/> <!-- fwd relative-->
    <axis xyz="0.8481 -0.2952 -0.4399"/>
  </joint>

  <link name="thumb_3">
    <visual>
      <geometry>
        <mesh filename="file:///home/patrick/contact/contact-sim/urdf/mesh/joint_15.stl" scale="1 1 1"/>
      </geometry>
      <origin xyz="0.0000 0.0000 0.0000" rpy="0.0000 0.0000 0.0000"/> <!-- inverse global -->
    </visual>
    <collision>
      <geometry>
        <mesh filename="file:///home/patrick/contact/contact-sim/urdf/mesh/joint_15.stl" scale="1 1 1"/>
      </geometry>
      <origin xyz="0.0000 0.0000 0.0000" rpy="0.0000 0.0000 0.0000"/> <!-- inverse global -->
    </collision>
  </link>
</robot>
